# 문제 2

다음은 실행도중에 예외가 발생하여 화면에 출력된 내용입니다.
이에 대한 설명 중 옳지 않은 것은 무엇일까요?

```
java.lang.ArithmeticException : / by zero
    at ExceptionEx18.method2(ExceptionEx18.java:12)
    at ExceptionEx18.method1(ExceptionEx18.java:8)
    at ExceptionEx18.main(ExcpetionEx18.java:4)
```

- 위의 내용으로 예외가 발생했을 당시 호출스택(call stack)에 존재했던 메소드를 알 수 있습니다.
  - 맞습니다. 2~4번째 줄을 보면 method2에서 예외가 발생했고 method2에서 발생한 예외를 method2 메소드를 호출한 메소드에게 책임을 넘기고 있습니다. 그리고 method1 메소드 또한 예외책임을 main 메소드로 넘기고 있습니다. 따라서 이러한 흐름을 보면 호출스택에는 밑에서부터 main - method1 -method2인 것을 알 수 있습니다.
- 예외가 발생한 위치는 method2 메서드이며, Exception18.java 파일의 12번째 줄이다.
  - 맞습니다. 출력 결과에서 제일 먼저 등장하는 메소드가 예외가 발생한 메소드 입니다. 그리고 괄호에는 예외가 발생한 파일명과 위치를 알 수 있습니다.
- 발생한 예외는 ArithmeticException이며, 0으로 나누어서 예외가 발생했다.
  - 맞습니다.
- method2 메소드가 method1 메소드를 호출하였고 그 위치는 ExceptionEx18.java 파일의 8번째 줄이다.
  - 틀렸습니다. method2는 method1 메소드를 호출한 것이 아니라 예외 책임을 자신을 호출해준 메소드에게 넘긴 것입니다.그리고 method2 메소드에서 method1 메소드를 호출한 위치가 ExceptionEx18.java 파일의 8번째 줄입니다.
